<?xml version="1.0" ?>
<!-- =================================================================================== -->
<!-- |    This document was autogenerated by xacro from uthai.urdf.xacro               | -->
<!-- |    EDITING THIS FILE BY HAND IS NOT RECOMMENDED                                 | -->
<!-- =================================================================================== -->
<robot name="uthai" xmlns:xacro="http://www.ros.org/wiki/xacro">
  <material name="black">
    <color rgba="0.0 0.0 0.0 1.0"/>
  </material>
  <material name="blue">
    <color rgba="0.0 0.0 0.8 1.0"/>
  </material>
  <material name="green">
    <color rgba="0.0 0.8 0.0 1.0"/>
  </material>
  <material name="grey">
    <color rgba="0.6 0.6 0.6 1.0"/>
  </material>
  <material name="orange">
    <color rgba="1.0 0.423529411765 0.0392156862745 1.0"/>
  </material>
  <material name="brown">
    <color rgba="0.870588235294 0.811764705882 0.764705882353 1.0"/>
  </material>
  <material name="red">
    <color rgba="0.8 0.0 0.0 1.0"/>
  </material>
  <material name="white">
    <color rgba="1.0 1.0 1.0 1.0"/>
  </material>
  <!-- ros_control plugin -->
  <gazebo>
    <plugin filename="libgazebo_ros_control.so" name="gazebo_ros_control">
      <robotNamespace>/uthai</robotNamespace>
    </plugin>
  </gazebo>
  <gazebo>
    <plugin filename="libgazebo_ros_p3d.so" name="ground_truth">
      <frameName>map</frameName>
      <bodyName>base_link</bodyName>
      <topicName>/uthai/odom</topicName>
      <updateRate>100.0</updateRate>
    </plugin>
  </gazebo>
  <!-- <gazebo><plugin name="imu_plugin" filename="libgazebo_ros_imu.so"><alwaysOn>true</alwaysOn><bodyName>imu_link</bodyName><topicName>/uthai/sensor/imu</topicName><serviceName>imu_service</serviceName><gaussianNoise>0.0</gaussianNoise><updateRate>10.0</updateRate><imu><noise><type>gaussian</type><rate><mean>0.0</mean><stddev>2e-4</stddev><bias_mean>0.0000075</bias_mean><bias_stddev>0.0000008</bias_stddev></rate><accel><mean>0.0</mean><stddev>1.7e-2</stddev><bias_mean>0.1</bias_mean><bias_stddev>0.001</bias_stddev></accel></noise></imu></plugin></gazebo>-->
  <!-- imu sensor -->
  <gazebo reference="imu_link">
    <gravity>true</gravity>
    <sensor name="imu_sensor" type="imu">
      <always_on>true</always_on>
      <update_rate>100</update_rate>
      <visualize>true</visualize>
      <topic>/uthai/sensor/imu</topic>
      <plugin filename="libgazebo_ros_imu_sensor.so" name="imu_plugin">
        <topicName>uthai/sensor/imu</topicName>
        <bodyName>imu_link</bodyName>
        <updateRateHZ>10.0</updateRateHZ>
        <gaussianNoise>0.0</gaussianNoise>
        <xyzOffset>0 0 0</xyzOffset>
        <rpyOffset>0 0 0</rpyOffset>
        <frameName>imu_link</frameName>
      </plugin>
      <pose>0 0 0 0 0 0</pose>
    </sensor>
  </gazebo>
  <!-- World -->
  <!--<gazebo reference="world"></gazebo>-->
  <!-- Base -->
  <gazebo reference="base_link"/>
  <!-- IMU -->
  <gazebo reference="imu_link"/>
  <!-- Body-->
  <gazebo reference="base_footprint">
    <mu1>0.2</mu1>
    <mu2>0.2</mu2>
    <material>Gazebo/Grey</material>
    <selfCollide>false</selfCollide>
  </gazebo>
  <!-- Left Leg -->
  <gazebo reference="l_hip_yaw_link">
    <mu1>0.2</mu1>
    <mu2>0.2</mu2>
    <material>Gazebo/Grey</material>
    <selfCollide>false</selfCollide>
  </gazebo>
  <gazebo reference="l_hip_roll_link">
    <mu1>0.2</mu1>
    <mu2>0.2</mu2>
    <material>Gazebo/Grey</material>
    <selfCollide>false</selfCollide>
  </gazebo>
  <gazebo reference="l_hip_pitch_link">
    <mu1>0.2</mu1>
    <mu2>0.2</mu2>
    <material>Gazebo/Grey</material>
    <selfCollide>false</selfCollide>
  </gazebo>
  <gazebo reference="l_knee_pitch_link">
    <mu1>0.2</mu1>
    <mu2>0.2</mu2>
    <material>Gazebo/Grey</material>
    <selfCollide>false</selfCollide>
  </gazebo>
  <gazebo reference="l_ankle_pitch_link">
    <mu1>0.2</mu1>
    <mu2>0.2</mu2>
    <material>Gazebo/Grey</material>
    <selfCollide>false</selfCollide>
  </gazebo>
  <gazebo reference="l_ankle_roll_link">
    <kp>100000.0</kp>
    <kd>100.0</kd>
    <mu1>1.5</mu1>
    <mu2>1.5</mu2>
    <!--<maxContacts>30</maxContacts>-->
    <fdir1>1 0 0</fdir1>
    <maxVel>1.0</maxVel>
    <minDepth>0.001</minDepth>
    <material>Gazebo/Blue</material>
  </gazebo>
  <!-- Right Leg -->
  <gazebo reference="r_hip_yaw_link">
    <mu1>0.2</mu1>
    <mu2>0.2</mu2>
    <material>Gazebo/Grey</material>
    <selfCollide>false</selfCollide>
  </gazebo>
  <gazebo reference="r_hip_roll_link">
    <mu1>0.2</mu1>
    <mu2>0.2</mu2>
    <material>Gazebo/Grey</material>
    <selfCollide>false</selfCollide>
  </gazebo>
  <gazebo reference="r_hip_pitch_link">
    <mu1>0.2</mu1>
    <mu2>0.2</mu2>
    <material>Gazebo/Grey</material>
    <selfCollide>false</selfCollide>
  </gazebo>
  <gazebo reference="r_knee_pitch_link">
    <mu1>0.2</mu1>
    <mu2>0.2</mu2>
    <material>Gazebo/Grey</material>
    <selfCollide>false</selfCollide>
  </gazebo>
  <gazebo reference="r_ankle_pitch_link">
    <mu1>0.2</mu1>
    <mu2>0.2</mu2>
    <material>Gazebo/Grey</material>
    <selfCollide>false</selfCollide>
  </gazebo>
  <gazebo reference="r_ankle_roll_link">
    <kp>100000.0</kp>
    <kd>100.0</kd>
    <mu1>1.5</mu1>
    <mu2>1.5</mu2>
    <!--<maxContacts>30</maxContacts>-->
    <fdir1>1 0 0</fdir1>
    <maxVel>1.0</maxVel>
    <minDepth>0.0001</minDepth>
    <material>Gazebo/Blue</material>
  </gazebo>
  <!-- Used for fixing robot -->
  <!-- <link name="world"></link> -->
  <!-- <joint name="world_fixed" type="fixed"><origin xyz="0 0 0.756" rpy="0 0 0"/><parent link="world"/><child link="base"/></joint> -->
  <link name="base_link"/>
  <joint name="base_fixed" type="fixed">
    <origin rpy="0 0 0" xyz="0 0 0"/>
    <parent link="base_link"/>
    <child link="base_footprint"/>
  </joint>
  <!-- base_link -->
  <link name="base_footprint">
    <visual>
      <origin rpy="0 0 0" xyz="0 0 0"/>
      <geometry>
        <mesh filename="package://uthai_description/meshes/base.STL" scale="1 1 1"/>
      </geometry>
      <material name="grey"/>
    </visual>
    <collision>
      <origin rpy="0 0 0" xyz="0 0 0"/>
      <geometry>
        <mesh filename="package://uthai_description/meshes/base.STL" scale="1 1 1"/>
      </geometry>
      <material name="grey"/>
    </collision>
    <inertial>
      <origin xyz="-0.00557436 0.00000000 -0.02356598"/>
      <mass value="0.86500000"/>
      <inertia ixx="0.00656431" ixy="-0.00000003" ixz="-0.00000466" iyy="0.00067608" iyz="0.00000000" izz="0.00664141"/>
    </inertial>
  </link>
  <!-- imu joint -->
  <joint name="imu_fixed" type="fixed">
    <origin rpy="0 0 0" xyz="0.0 0 0.45"/>
    <parent link="base_footprint"/>
    <child link="imu_link"/>
  </joint>
  <link name="imu_link"/>
  <!-- right hip yaw joint -->
  <joint name="r_hip_yaw_joint" type="revolute">
    <axis xyz="0 0 1"/>
    <origin rpy="0 0 -1.570796327" xyz="0.008 -0.09 -0.06"/>
    <parent link="base_footprint"/>
    <child link="r_hip_yaw_link"/>
    <limit effort="1000" lower="-2.8274333886" upper="2.8274333886" velocity="100"/>
    <dynamics damping="0.1" friction="0.0"/>
  </joint>
  <transmission name="r_hip_yaw_joint_tran">
    <type>transmission_interface/SimpleTransmission</type>
    <joint name="r_hip_yaw_joint">
      <hardwareInterface>EffortJointInterface</hardwareInterface>
    </joint>
    <actuator name="r_hip_yaw_joint_motor">
      <hardwareInterface>EffortJointInterface</hardwareInterface>
      <mechanicalReduction>1</mechanicalReduction>
    </actuator>
  </transmission>
  <!-- right hip yaw link -->
  <link name="r_hip_yaw_link">
    <visual>
      <origin rpy="0 0 0" xyz="0 0 0"/>
      <geometry>
        <mesh filename="package://uthai_description/meshes/r_hip_yaw.STL" scale="1 1 1"/>
      </geometry>
      <material name="grey"/>
    </visual>
    <collision>
      <origin rpy="0 0 0" xyz="0 0 0"/>
      <geometry>
        <mesh filename="package://uthai_description/meshes/r_hip_yaw.STL" scale="1 1 1"/>
      </geometry>
      <material name="grey"/>
    </collision>
    <inertial>
      <origin xyz="0.00000000 -0.02500000 -0.00735017"/>
      <mass value="0.09100000"/>
      <inertia ixx="0.00014158" ixy="0.00000000" ixz="0.00000000" iyy="0.00002022" iyz="0.00000000" izz="0.00014316"/>
    </inertial>
  </link>
  <!-- right hip roll joint-->
  <joint name="r_hip_roll_joint" type="revolute">
    <axis xyz="0 0 1"/>
    <origin rpy="1.570796327 0 3.141592654" xyz="0 0 -0.036"/>
    <parent link="r_hip_yaw_link"/>
    <child link="r_hip_roll_link"/>
    <limit effort="1000" lower="-2.8274333886" upper="2.8274333886" velocity="100"/>
    <dynamics damping="0.1" friction="0.0"/>
  </joint>
  <transmission name="r_hip_roll_joint_tran">
    <type>transmission_interface/SimpleTransmission</type>
    <joint name="r_hip_roll_joint">
      <hardwareInterface>EffortJointInterface</hardwareInterface>
    </joint>
    <actuator name="r_hip_roll_joint_motor">
      <hardwareInterface>EffortJointInterface</hardwareInterface>
      <mechanicalReduction>1</mechanicalReduction>
    </actuator>
  </transmission>
  <!-- right hip roll link -->
  <link name="r_hip_roll_link">
    <visual>
      <origin rpy="0 0 0" xyz="0 0 0"/>
      <geometry>
        <mesh filename="package://uthai_description/meshes/r_hip_roll.STL" scale="1 1 1"/>
      </geometry>
      <material name="grey"/>
    </visual>
    <collision>
      <origin rpy="0 0 0" xyz="0 0 0"/>
      <geometry>
        <mesh filename="package://uthai_description/meshes/r_hip_roll.STL" scale="1 1 1"/>
      </geometry>
      <material name="grey"/>
    </collision>
    <inertial>
      <origin xyz="0.00000000 -0.01526210 -0.02652545"/>
      <mass value="0.34300000"/>
      <inertia ixx="0.00032449" ixy="0.00000081" ixz="0.00000000" iyy="0.00026847" iyz="0.00000219" izz="0.00014760"/>
    </inertial>
  </link>
  <!-- right hip pitch joint -->
  <joint name="r_hip_pitch_joint" type="revolute">
    <axis xyz="0 0 1"/>
    <origin rpy="-1.570796327 0 -1.570796327" xyz="0 0 -0.005"/>
    <parent link="r_hip_roll_link"/>
    <child link="r_hip_pitch_link"/>
    <limit effort="1000" lower="-2.8274333886" upper="2.8274333886" velocity="100"/>
    <dynamics damping="0.1" friction="0.0"/>
  </joint>
  <transmission name="r_hip_pitch_joint_tran">
    <type>transmission_interface/SimpleTransmission</type>
    <joint name="r_hip_pitch_joint">
      <hardwareInterface>EffortJointInterface</hardwareInterface>
    </joint>
    <actuator name="r_hip_pitch_joint_motor">
      <hardwareInterface>EffortJointInterface</hardwareInterface>
      <mechanicalReduction>1</mechanicalReduction>
    </actuator>
  </transmission>
  <!-- right hip pitch link -->
  <link name="r_hip_pitch_link">
    <visual>
      <origin rpy="0 0 0" xyz="0 0 0"/>
      <geometry>
        <mesh filename="package://uthai_description/meshes/r_hip_pitch.STL" scale="1 1 1"/>
      </geometry>
      <material name="grey"/>
    </visual>
    <collision>
      <origin rpy="0 0 0" xyz="0 0 0"/>
      <geometry>
        <mesh filename="package://uthai_description/meshes/r_hip_pitch.STL" scale="1 1 1"/>
      </geometry>
      <material name="grey"/>
    </collision>
    <inertial>
      <origin xyz="0.22137989 0.00000000 0.00000000"/>
      <mass value="0.31800000"/>
      <inertia ixx="0.00011525" ixy="0.00000000" ixz="0.00000078" iyy="0.00254669" iyz="0.00000000" izz="0.00250848"/>
    </inertial>
  </link>
  <!-- right knee pitch joint -->
  <joint name="r_knee_pitch_joint" type="revolute">
    <axis xyz="0 0 1"/>
    <origin rpy="0 0 0" xyz="0.3 0 0"/>
    <parent link="r_hip_pitch_link"/>
    <child link="r_knee_pitch_link"/>
    <limit effort="1000" lower="-2.8274333886" upper="2.8274333886" velocity="100"/>
    <dynamics damping="0.1" friction="0.0"/>
  </joint>
  <transmission name="r_knee_pitch_joint_tran">
    <type>transmission_interface/SimpleTransmission</type>
    <joint name="r_knee_pitch_joint">
      <hardwareInterface>EffortJointInterface</hardwareInterface>
    </joint>
    <actuator name="r_knee_pitch_joint_motor">
      <hardwareInterface>EffortJointInterface</hardwareInterface>
      <mechanicalReduction>1</mechanicalReduction>
    </actuator>
  </transmission>
  <!-- right knee pitch link -->
  <link name="r_knee_pitch_link">
    <visual>
      <origin rpy="0 0 0" xyz="0 0 0"/>
      <geometry>
        <mesh filename="package://uthai_description/meshes/r_knee_pitch.STL" scale="1 1 1"/>
      </geometry>
      <material name="grey"/>
    </visual>
    <collision>
      <origin rpy="0 0 0" xyz="0 0 0"/>
      <geometry>
        <mesh filename="package://uthai_description/meshes/r_knee_pitch.STL" scale="1 1 1"/>
      </geometry>
      <material name="grey"/>
    </collision>
    <inertial>
      <origin xyz="0.16288218 0.00000000 0.00000000"/>
      <mass value="0.15100000"/>
      <inertia ixx="0.00006340" ixy="0.0" ixz="0.0" iyy="0.00139612" iyz="0.0" izz="0.00136731"/>
    </inertial>
  </link>
  <!-- right ankle pitch joint -->
  <joint name="r_ankle_pitch_joint" type="revolute">
    <axis xyz="0 0 1"/>
    <origin rpy="0 0 0" xyz="0.315 0 0"/>
    <parent link="r_knee_pitch_link"/>
    <child link="r_ankle_pitch_link"/>
    <limit effort="1000" lower="-2.8274333886" upper="2.8274333886" velocity="100"/>
    <dynamics damping="0.1" friction="0.0"/>
  </joint>
  <transmission name="r_ankle_pitch_joint_tran">
    <type>transmission_interface/SimpleTransmission</type>
    <joint name="r_ankle_pitch_joint">
      <hardwareInterface>EffortJointInterface</hardwareInterface>
    </joint>
    <actuator name="r_ankle_pitch_joint_motor">
      <hardwareInterface>EffortJointInterface</hardwareInterface>
      <mechanicalReduction>1</mechanicalReduction>
    </actuator>
  </transmission>
  <!-- right ankle pitch link -->
  <link name="r_ankle_pitch_link">
    <visual>
      <origin rpy="0 0 0" xyz="0 0 0"/>
      <geometry>
        <mesh filename="package://uthai_description/meshes/r_ankle_pitch.STL" scale="1 1 1"/>
      </geometry>
      <material name="grey"/>
    </visual>
    <collision>
      <origin rpy="0 0 0" xyz="0 0 0"/>
      <geometry>
        <mesh filename="package://uthai_description/meshes/r_ankle_pitch.STL" scale="1 1 1"/>
      </geometry>
      <material name="grey"/>
    </collision>
    <inertial>
      <origin xyz="-0.01526210 0.02152545 0.00000000"/>
      <mass value="0.34300000"/>
      <inertia ixx="0.00026847" ixy="-0.00000219" ixz="-0.00000081" iyy="0.00014760" iyz="0.00000000" izz="0.00032449"/>
    </inertial>
  </link>
  <!-- right ankle roll pitch -->
  <joint name="r_ankle_roll_joint" type="revolute">
    <axis xyz="0 0 1"/>
    <origin rpy="1.570796327 0 0" xyz="0 0 0"/>
    <parent link="r_ankle_pitch_link"/>
    <child link="r_ankle_roll_link"/>
    <limit effort="1000" lower="-2.8274333886" upper="2.8274333886" velocity="100"/>
    <dynamics damping="0.1" friction="0.0"/>
  </joint>
  <transmission name="r_ankle_roll_joint_tran">
    <type>transmission_interface/SimpleTransmission</type>
    <joint name="r_ankle_roll_joint">
      <hardwareInterface>EffortJointInterface</hardwareInterface>
    </joint>
    <actuator name="r_ankle_roll_joint_motor">
      <hardwareInterface>EffortJointInterface</hardwareInterface>
      <mechanicalReduction>1</mechanicalReduction>
    </actuator>
  </transmission>
  <!-- right ankle roll link -->
  <link name="r_ankle_roll_link">
    <visual>
      <origin rpy="0 0 0" xyz="0 0 0"/>
      <geometry>
        <mesh filename="package://uthai_description/meshes/r_ankle_roll.STL" scale="1 1 1"/>
      </geometry>
      <material name="grey"/>
    </visual>
    <collision>
      <origin rpy="0 0 0" xyz="0 0 0"/>
      <geometry>
        <mesh filename="package://uthai_description/meshes/r_ankle_roll.STL" scale="1 1 1"/>
      </geometry>
      <material name="grey"/>
    </collision>
    <inertial>
      <origin xyz="0.03625882 -0.00019548 0.00034576"/>
      <mass value="0.10500000"/>
      <inertia ixx="0.00034591" ixy="-0.00000013" ixz="0.00000857" iyy="0.00032705" iyz="0.00000120" izz="0.00004813"/>
    </inertial>
  </link>
  <!-- right ft fixed joint -->
  <!--<joint name="r_ft_fixed" type="fixed">
            <origin xyz="0.045 0.0 0.0" rpy="0 ${-pi/2} 0"/>
            <parent link="r_ankle_roll_link"/>
            <child link="r_foot_ft_link"/>
        </joint>-->
  <!-- right foot ft link -->
  <!--<link name="r_foot_ft_link"></link>-->
  <!-- left hip yaw joint -->
  <joint name="l_hip_yaw_joint" type="revolute">
    <axis xyz="0 0 1"/>
    <origin rpy="0 0 1.570796327" xyz="0.008 0.09 -0.06"/>
    <parent link="base_footprint"/>
    <child link="l_hip_yaw_link"/>
    <limit effort="1000" lower="-2.8274333886" upper="2.8274333886" velocity="100"/>
    <dynamics damping="0.1" friction="0.0"/>
  </joint>
  <transmission name="l_hip_yaw_joint_tran">
    <type>transmission_interface/SimpleTransmission</type>
    <joint name="l_hip_yaw_joint">
      <hardwareInterface>EffortJointInterface</hardwareInterface>
    </joint>
    <actuator name="l_hip_yaw_joint_motor">
      <hardwareInterface>EffortJointInterface</hardwareInterface>
      <mechanicalReduction>1</mechanicalReduction>
    </actuator>
  </transmission>
  <!-- left hip yaw link -->
  <link name="l_hip_yaw_link">
    <visual>
      <origin rpy="0 0 0" xyz="0 0 0"/>
      <geometry>
        <mesh filename="package://uthai_description/meshes/l_hip_yaw.STL" scale="1 1 1"/>
      </geometry>
      <material name="grey"/>
    </visual>
    <collision>
      <origin rpy="0 0 0" xyz="0 0 0"/>
      <geometry>
        <mesh filename="package://uthai_description/meshes/l_hip_yaw.STL" scale="1 1 1"/>
      </geometry>
      <material name="grey"/>
    </collision>
    <inertial>
      <origin xyz="0.00000000 0.02500000 -0.00735017"/>
      <mass value="0.09100000"/>
      <inertia ixx="0.00014158" ixy="0.0" ixz="0.0" iyy="0.00002022" iyz="0.0" izz="0.00014316"/>
    </inertial>
  </link>
  <!-- left hip roll joint-->
  <joint name="l_hip_roll_joint" type="revolute">
    <axis xyz="0 0 1"/>
    <origin rpy="1.570796327 0 0" xyz="0 0 -0.036"/>
    <parent link="l_hip_yaw_link"/>
    <child link="l_hip_roll_link"/>
    <limit effort="1000" lower="-2.8274333886" upper="2.8274333886" velocity="100"/>
    <dynamics damping="0.1" friction="0.0"/>
  </joint>
  <transmission name="l_hip_roll_joint_tran">
    <type>transmission_interface/SimpleTransmission</type>
    <joint name="l_hip_roll_joint">
      <hardwareInterface>EffortJointInterface</hardwareInterface>
    </joint>
    <actuator name="l_hip_roll_joint_motor">
      <hardwareInterface>EffortJointInterface</hardwareInterface>
      <mechanicalReduction>1</mechanicalReduction>
    </actuator>
  </transmission>
  <!-- left hip roll link -->
  <link name="l_hip_roll_link">
    <visual>
      <origin rpy="0 0 0" xyz="0 0 0"/>
      <geometry>
        <mesh filename="package://uthai_description/meshes/l_hip_roll.STL" scale="1 1 1"/>
      </geometry>
      <material name="grey"/>
    </visual>
    <collision>
      <origin rpy="0 0 0" xyz="0 0 0"/>
      <geometry>
        <mesh filename="package://uthai_description/meshes/l_hip_roll.STL" scale="1 1 1"/>
      </geometry>
      <material name="grey"/>
    </collision>
    <inertial>
      <origin xyz="0.00000000 -0.01526210 -0.02652545"/>
      <mass value="0.34300000"/>
      <inertia ixx="0.00032449" ixy="-0.00000081" ixz="0.00000000" iyy="0.00026847" iyz="0.00000219" izz="0.00014760"/>
    </inertial>
  </link>
  <!-- left hip pitch joint -->
  <joint name="l_hip_pitch_joint" type="revolute">
    <axis xyz="0 0 1"/>
    <origin rpy="-1.570796327 0 -1.570796327" xyz="0 0 -0.005"/>
    <parent link="l_hip_roll_link"/>
    <child link="l_hip_pitch_link"/>
    <limit effort="1000" lower="-2.8274333886" upper="2.8274333886" velocity="100"/>
    <dynamics damping="0.1" friction="0.0"/>
  </joint>
  <transmission name="l_hip_pitch_joint_tran">
    <type>transmission_interface/SimpleTransmission</type>
    <joint name="l_hip_pitch_joint">
      <hardwareInterface>EffortJointInterface</hardwareInterface>
    </joint>
    <actuator name="l_hip_pitch_joint_motor">
      <hardwareInterface>EffortJointInterface</hardwareInterface>
      <mechanicalReduction>1</mechanicalReduction>
    </actuator>
  </transmission>
  <!-- left hip pitch link -->
  <link name="l_hip_pitch_link">
    <visual>
      <origin rpy="0 0 0" xyz="0 0 0"/>
      <geometry>
        <mesh filename="package://uthai_description/meshes/l_hip_pitch.STL" scale="1 1 1"/>
      </geometry>
      <material name="grey"/>
    </visual>
    <collision>
      <origin rpy="0 0 0" xyz="0 0 0"/>
      <geometry>
        <mesh filename="package://uthai_description/meshes/l_hip_pitch.STL" scale="1 1 1"/>
      </geometry>
      <material name="grey"/>
    </collision>
    <inertial>
      <origin xyz="0.22137989 0.00000000 0.00000000"/>
      <mass value="0.31800000"/>
      <inertia ixx="0.00011525" ixy="0.00000000" ixz="0.00000078" iyy="0.00254669" iyz="0.00000000" izz="0.00250848"/>
    </inertial>
  </link>
  <!-- left knee pitch joint -->
  <joint name="l_knee_pitch_joint" type="revolute">
    <axis xyz="0 0 1"/>
    <origin rpy="0 0 0" xyz="0.3 0 0"/>
    <parent link="l_hip_pitch_link"/>
    <child link="l_knee_pitch_link"/>
    <limit effort="1000" lower="-2.8274333886" upper="2.8274333886" velocity="100"/>
    <dynamics damping="0.1" friction="0.0"/>
  </joint>
  <transmission name="l_knee_pitch_joint_tran">
    <type>transmission_interface/SimpleTransmission</type>
    <joint name="l_knee_pitch_joint">
      <hardwareInterface>EffortJointInterface</hardwareInterface>
    </joint>
    <actuator name="l_knee_pitch_joint_motor">
      <hardwareInterface>EffortJointInterface</hardwareInterface>
      <mechanicalReduction>1</mechanicalReduction>
    </actuator>
  </transmission>
  <!-- left knee pitch link -->
  <link name="l_knee_pitch_link">
    <visual>
      <origin rpy="0 0 0" xyz="0 0 0"/>
      <geometry>
        <mesh filename="package://uthai_description/meshes/l_knee_pitch.STL" scale="1 1 1"/>
      </geometry>
      <material name="grey"/>
    </visual>
    <collision>
      <origin rpy="0 0 0" xyz="0 0 0"/>
      <geometry>
        <mesh filename="package://uthai_description/meshes/l_knee_pitch.STL" scale="1 1 1"/>
      </geometry>
      <material name="grey"/>
    </collision>
    <inertial>
      <origin xyz="0.16288218 0.00000000 0.00000000"/>
      <mass value="0.15100000"/>
      <inertia ixx="0.00006340" ixy="0.0" ixz="0.0" iyy="0.00139612" iyz="0.0" izz="0.00136731"/>
    </inertial>
  </link>
  <!-- left ankle pitch joint -->
  <joint name="l_ankle_pitch_joint" type="revolute">
    <axis xyz="0 0 1"/>
    <origin rpy="0 0 0" xyz="0.315 0 0"/>
    <parent link="l_knee_pitch_link"/>
    <child link="l_ankle_pitch_link"/>
    <limit effort="1000" lower="-2.8274333886" upper="2.8274333886" velocity="100"/>
    <dynamics damping="0.1" friction="0.0"/>
  </joint>
  <transmission name="l_ankle_pitch_joint_tran">
    <type>transmission_interface/SimpleTransmission</type>
    <joint name="l_ankle_pitch_joint">
      <hardwareInterface>EffortJointInterface</hardwareInterface>
    </joint>
    <actuator name="l_ankle_pitch_joint_motor">
      <hardwareInterface>EffortJointInterface</hardwareInterface>
      <mechanicalReduction>1</mechanicalReduction>
    </actuator>
  </transmission>
  <!-- left ankle pitch link -->
  <link name="l_ankle_pitch_link">
    <visual>
      <origin rpy="0 0 0" xyz="0 0 0"/>
      <geometry>
        <mesh filename="package://uthai_description/meshes/l_ankle_pitch.STL" scale="1 1 1"/>
      </geometry>
      <material name="grey"/>
    </visual>
    <collision>
      <origin rpy="0 0 0" xyz="0 0 0"/>
      <geometry>
        <mesh filename="package://uthai_description/meshes/l_ankle_pitch.STL" scale="1 1 1"/>
      </geometry>
      <material name="grey"/>
    </collision>
    <inertial>
      <origin xyz="-0.01526210 0.02152545 0.00000000"/>
      <mass value="0.34300000"/>
      <inertia ixx="0.00026847" ixy="-0.00000219" ixz="-0.00000081" iyy="0.00014760" iyz="0.00000000" izz="0.00032449"/>
    </inertial>
  </link>
  <!-- left ankle roll pitch -->
  <joint name="l_ankle_roll_joint" type="revolute">
    <axis xyz="0 0 1"/>
    <origin rpy="1.570796327 0 0" xyz="0 0 0"/>
    <parent link="l_ankle_pitch_link"/>
    <child link="l_ankle_roll_link"/>
    <limit effort="1000" lower="-2.8274333886" upper="2.8274333886" velocity="100"/>
    <dynamics damping="0.1" friction="0.0"/>
  </joint>
  <transmission name="l_ankle_roll_joint_tran">
    <type>transmission_interface/SimpleTransmission</type>
    <joint name="l_ankle_roll_joint">
      <hardwareInterface>EffortJointInterface</hardwareInterface>
    </joint>
    <actuator name="l_ankle_roll_joint_motor">
      <hardwareInterface>EffortJointInterface</hardwareInterface>
      <mechanicalReduction>1</mechanicalReduction>
    </actuator>
  </transmission>
  <!-- left ankle roll link -->
  <link name="l_ankle_roll_link">
    <visual>
      <origin rpy="0 0 0" xyz="0 0 0"/>
      <geometry>
        <mesh filename="package://uthai_description/meshes/l_ankle_roll.STL" scale="1 1 1"/>
      </geometry>
      <material name="grey"/>
    </visual>
    <collision>
      <origin rpy="0 0 0" xyz="0 0 0"/>
      <geometry>
        <mesh filename="package://uthai_description/meshes/l_ankle_roll.STL" scale="1 1 1"/>
      </geometry>
      <material name="grey"/>
    </collision>
    <inertial>
      <origin xyz="0.03608455 0.00020160 0.00002697"/>
      <mass value="0.10500000"/>
      <inertia ixx="0.00034223" ixy="0.00000014" ixz="0.00000840" iyy="0.00032348" iyz="-0.00000118" izz="0.00004816"/>
    </inertial>
  </link>
  <!-- left ft fixed joint -->
  <!--<joint name="l_ft_fixed" type="fixed">
            <origin xyz="0.045 0.0 0.0" rpy="0 ${-pi/2} 0"/>
            <parent link="l_ankle_roll_link"/>
            <child link="l_foot_ft_link"/>
        </joint>-->
  <!-- left foot ft link -->
  <!--<link name="l_foot_ft_link"></link>-->
</robot>
