<?xml version="1.0"?>
<robot name="uthai_humanoid" 
    xmlns:xacro="http://www.ros.org/wiki/xacro">
    <!--Uthai Humanoid, FIBO, KMUTT, Thailand, 2017-->
    <!--This file generated by Liews Wuttipat-->
    <!--Inertia perameters -->
    <xacro:property name="pi" value="3.14159265"/>
    <xacro:property name="base_mass" value="4.0"/>
    <xacro:property name="link1_mass" value="4.0"/>
    <xacro:property name="link1_cog" value="0.0 0.0 0.0"/>
    <xacro:include filename="$(find uthai_description)/urdf/uthai_materials.xacro" />
    <xacro:include filename="$(find uthai_description)/urdf/uthai_macros.xacro" />
    <link name="base_link"/>
    <link name="body">
        <visualize fname="body.STL"/>
    </link>
    <joint name="base_link_to_body" type="fixed">
        <parent link="base_link"/>
        <child link="body"/>
    </joint>
    <link name="r_hip_yaw">
        <visualize fname="r_hip_yaw.STL"/>
    </link>
    <link name="r_hip_pitch">
        <visualize fname="r_hip_pitch.STL"/>
    </link>
    <link name="r_hip_roll">
        <visualize fname="r_hip_roll.STL"/>
    </link>
    <link name="r_knee_pitch">
        <visualize fname="r_knee_pitch.STL"/>
    </link>
    <link name="r_ankle_pitch">
        <visualize fname="r_ankle_pitch.STL"/>
    </link>
    <link name="r_ankle_roll">
        <visualize fname="r_ankle_roll.STL"/>
    </link>
    <link name="r_foot"/>
    <link name="r_foot_ref"/>
    <joint name="r_j_hip_yaw" type="revolute">
        <origin rpy="0 0 ${-pi/2}" xyz="-0.005 -0.0375 -0.0375"/>
        <parent link="body"/>
        <child link="r_hip_yaw"/>
        <axis xyz="0 0 1"/>
        <limit effort="10" lower="-2.6179939" upper="2.6179939" velocity="5.6548668"/>
    </joint>
    <joint name="r_j_hip_roll" type="revolute">
        <origin rpy="${pi/2} 0 ${pi}" xyz="0 0 -0.0315"/>
        <parent link="r_hip_yaw"/>
        <child link="r_hip_roll"/>
        <axis xyz="0 0 1"/>
        <limit effort="10" lower="-2.6179939" upper="2.6179939" velocity="5.6548668"/>
    </joint>
    <joint name="r_j_hip_pitch" type="revolute">
        <origin rpy="${-pi/2} 0 ${-pi/2}" xyz="0 0 0"/>
        <parent link="r_hip_roll"/>
        <child link="r_hip_pitch"/>
        <axis xyz="0 0 1"/>
        <limit effort="10" lower="-2.6179939" upper="2.6179939" velocity="5.6548668"/>
    </joint>
    <joint name="r_j_knee_pitch" type="revolute">
        <origin rpy="0 0 0" xyz="0.0975 0 0"/>
        <parent link="r_hip_pitch"/>
        <child link="r_knee_pitch"/>
        <axis xyz="0 0 1"/>
        <limit effort="10" lower="-2.6179939" upper="2.6179939" velocity="5.6548668"/>
    </joint>
    <joint name="r_j_ankle_pitch" type="revolute">
        <origin rpy="0 0 0" xyz="0.098 0 0"/>
        <parent link="r_knee_pitch"/>
        <child link="r_ankle_pitch"/>
        <axis xyz="0 0 1"/>
        <limit effort="10" lower="-2.6179939" upper="2.6179939" velocity="5.6548668"/>
    </joint>
    <joint name="r_j_ankle_roll" type="revolute">
        <origin rpy="${pi/2} 0 0" xyz="0 0 0"/>
        <parent link="r_ankle_pitch"/>
        <child link="r_ankle_roll"/>
        <axis xyz="0 0 1"/>
        <limit effort="10" lower="-2.6179939" upper="2.6179939" velocity="5.6548668"/>
    </joint>
    <joint name="r_j_foot" type="fixed">
        <origin rpy="${-pi/2} 0 0" xyz="0.0335 0 0"/>
        <parent link="r_ankle_roll"/>
        <child link="r_foot"/>
    </joint>
    <joint name="r_j_foot_ref" type="fixed">
        <origin rpy="${pi/2} 0 ${-pi/2}" xyz="0 0 0"/>
        <parent link="r_foot"/>
        <child link="r_foot_ref"/>
    </joint>
    <link name="l_hip_yaw">
        <visualize fname="l_hip_yaw.STL"/>
    </link>
    <link name="l_hip_pitch">
        <visualize fname="l_hip_pitch.STL"/>
    </link>
    <link name="l_hip_roll">
        <visualize fname="l_hip_roll.STL"/>
    </link>
    <link name="l_knee_pitch">
        <visualize fname="l_knee_pitch.STL"/>
    </link>
    <link name="l_ankle_pitch">
        <visualize fname="l_ankle_pitch.STL"/>
    </link>
    <link name="l_ankle_roll">
        <visualize fname="l_ankle_roll.STL"/>
    </link>
    <link name="l_foot"/>
    <link name="l_foot_ref"/>
    <joint name="l_j_hip_yaw" type="revolute">
        <origin rpy="0 0 ${pi/2}" xyz="-0.005 0.037 -0.037"/>
        <parent link="body"/>
        <child link="l_hip_yaw"/>
        <axis xyz="0 0 1"/>
        <limit effort="10" lower="-2.6179939" upper="2.6179939" velocity="5.6548668"/>
    </joint>
    <joint name="l_j_hip_roll" type="revolute">
        <origin rpy="${pi/2} 0 0" xyz="0 0 -0.0315"/>
        <parent link="l_hip_yaw"/>
        <child link="l_hip_roll"/>
        <axis xyz="0 0 1"/>
        <limit effort="10" lower="-2.6179939" upper="2.6179939" velocity="5.6548668"/>
    </joint>
    <joint name="l_j_hip_pitch" type="revolute">
        <origin rpy="${-pi/2} 0 ${-pi/2}" xyz="0 0 0"/>
        <parent link="l_hip_roll"/>
        <child link="l_hip_pitch"/>
        <axis xyz="0 0 1"/>
        <limit effort="10" lower="-2.6179939" upper="2.6179939" velocity="5.6548668"/>
    </joint>
    <joint name="l_j_knee_pitch" type="revolute">
        <origin rpy="0 0 0" xyz="0.0975 0 0"/>
        <parent link="l_hip_pitch"/>
        <child link="l_knee_pitch"/>
        <axis xyz="0 0 1"/>
        <limit effort="10" lower="-2.6179939" upper="2.6179939" velocity="5.6548668"/>
    </joint>
    <joint name="l_j_ankle_pitch" type="revolute">
        <origin rpy="0 0 0" xyz="0.098 0 0"/>
        <parent link="l_knee_pitch"/>
        <child link="l_ankle_pitch"/>
        <axis xyz="0 0 1"/>
        <limit effort="10" lower="-2.6179939" upper="2.6179939" velocity="5.6548668"/>
    </joint>
    <joint name="l_j_ankle_roll" type="revolute">
        <origin rpy="${pi/2} 0 0" xyz="0 0 0"/>
        <parent link="l_ankle_pitch"/>
        <child link="l_ankle_roll"/>
        <axis xyz="0 0 1"/>
        <limit effort="10" lower="-2.6179939" upper="2.6179939" velocity="5.6548668"/>
    </joint>
    <joint name="l_j_foot" type="fixed">
        <origin rpy="${-pi/2} 0 0" xyz="0.0335 0 0"/>
        <parent link="l_ankle_roll"/>
        <child link="l_foot"/>
    </joint>
    <joint name="l_j_foot_ref" type="fixed">
        <origin rpy="${pi/2} 0 ${-pi/2}" xyz="0 0 0"/>
        <parent link="l_foot"/>
        <child link="l_foot_ref"/>
    </joint>
    <transmis jname="r_j_hip_yaw" />
    <transmis jname="r_j_hip_roll" />
    <transmis jname="r_j_hip_pitch" />
    <transmis jname="r_j_knee_pitch" />
    <transmis jname="r_j_ankle_pitch" />
    <transmis jname="r_j_ankle_roll" />
    <transmis jname="l_j_hip_yaw" />
    <transmis jname="l_j_hip_roll" />
    <transmis jname="l_j_hip_pitch" />
    <transmis jname="l_j_knee_pitch" />
    <transmis jname="l_j_ankle_pitch" />
    <transmis jname="l_j_ankle_roll" />
</robot>