<?xml version="1.0" ?>
<!-- =================================================================================== -->
<!-- |    This document was autogenerated by xacro from myRobot.xacro                  | -->
<!-- |    EDITING THIS FILE BY HAND IS NOT RECOMMENDED                                 | -->
<!-- =================================================================================== -->
<robot name="myRobot" xmlns:xacro="http://www.ros.org/wiki/xacro">
  <!--End Macro to make dummy link-->
  <link name="base_link"/>
  <link name="fd_base_link"/>
  <joint name="fixed_fd" type="fixed">
    <parent link="base_link"/>
    <child link="fd_base_link"/>
  </joint>
  <joint name="jd_0" type="fixed">
    <parent link="fd_base_link"/>
    <child link="f_0"/>
    <origin rpy="0.0 -0.0 -1.5707963267948966" xyz="5.51091059616e-18 -0.09 -0.055"/>
  </joint>
  <link name="f_0"/>
  <link name="fd_0"/>
  <joint name="j_1" type="revolute">
    <parent link="f_0"/>
    <child link="fd_0"/>
    <axis xyz="0 0 1"/>
    <limit effort="10" lower="-2.6179939" upper="2.6179939" velocity="5.6548668"/>
  </joint>
  <joint name="jd_1" type="fixed">
    <parent link="fd_0"/>
    <child link="f_1"/>
    <origin rpy="-1.5707963267948966 -0.0 1.5707963267948966" xyz="0.0 0.0 -0.04"/>
  </joint>
  <link name="f_1"/>
  <link name="fd_1"/>
  <joint name="j_2" type="revolute">
    <parent link="f_1"/>
    <child link="fd_1"/>
    <axis xyz="0 0 1"/>
    <limit effort="10" lower="-2.6179939" upper="2.6179939" velocity="5.6548668"/>
  </joint>
  <joint name="jd_2" type="fixed">
    <parent link="fd_1"/>
    <child link="f_2"/>
    <origin rpy="1.5707963267948966 -0.0 1.5707963267948966" xyz="0.0 0.0 0.0"/>
  </joint>
  <link name="f_2"/>
  <link name="fd_2"/>
  <joint name="j_3" type="revolute">
    <parent link="f_2"/>
    <child link="fd_2"/>
    <axis xyz="0 0 1"/>
    <limit effort="10" lower="-2.6179939" upper="2.6179939" velocity="5.6548668"/>
  </joint>
  <joint name="jd_3" type="fixed">
    <parent link="fd_2"/>
    <child link="f_3"/>
    <origin rpy="-1.5707963267948966 -0.0 0.0" xyz="0.3 0.0 0.0"/>
  </joint>
  <link name="f_3"/>
  <link name="fd_3"/>
  <joint name="j_4" type="revolute">
    <parent link="f_3"/>
    <child link="fd_3"/>
    <axis xyz="0 0 1"/>
    <limit effort="10" lower="-2.6179939" upper="2.6179939" velocity="5.6548668"/>
  </joint>
  <joint name="jd_4" type="fixed">
    <parent link="fd_3"/>
    <child link="f_4"/>
    <origin rpy="0.0 -0.0 0.0" xyz="0.315 0.0 0.0"/>
  </joint>
  <link name="f_4"/>
  <link name="fd_4"/>
  <joint name="j_5" type="revolute">
    <parent link="f_4"/>
    <child link="fd_4"/>
    <axis xyz="0 0 1"/>
    <limit effort="10" lower="-2.6179939" upper="2.6179939" velocity="5.6548668"/>
  </joint>
  <joint name="jd_5" type="fixed">
    <parent link="fd_4"/>
    <child link="f_5"/>
    <origin rpy="1.5707963267948966 -0.0 0.0" xyz="0.0 0.0 0.0"/>
  </joint>
  <link name="f_5"/>
  <link name="fd_5"/>
  <joint name="j_6" type="revolute">
    <parent link="f_5"/>
    <child link="fd_5"/>
    <axis xyz="0 0 1"/>
    <limit effort="10" lower="-2.6179939" upper="2.6179939" velocity="5.6548668"/>
  </joint>
  <joint name="jd_6" type="fixed">
    <parent link="fd_5"/>
    <child link="f_6"/>
    <origin rpy="-1.5707963267948966 -0.0 0.0" xyz="0.045 0.0 0.0"/>
  </joint>
  <link name="f_6"/>
  <link name="fd_6"/>
  <joint name="jf_1" type="fixed">
    <parent link="f_6"/>
    <child link="fd_6"/>
  </joint>
  <joint name="jd_7" type="fixed">
    <parent link="fd_6"/>
    <child link="f_7"/>
    <origin rpy="1.5707963267948966 -0.0 -1.5707963267948966" xyz="3.55147571753e-18 -0.058 0.0"/>
  </joint>
  <link name="f_7"/>
  <link name="fd_7"/>
  <joint name="jf_2" type="fixed">
    <parent link="f_7"/>
    <child link="fd_7"/>
  </joint>
  <joint name="jd_10" type="fixed">
    <parent link="fd_base_link"/>
    <child link="f_10"/>
    <origin rpy="0.0 -0.0 1.5707963267948966" xyz="5.51091059616e-18 0.09 -0.055"/>
  </joint>
  <link name="f_10"/>
  <link name="fd_10"/>
  <joint name="j_7" type="revolute">
    <parent link="f_10"/>
    <child link="fd_10"/>
    <axis xyz="0 0 1"/>
    <limit effort="10" lower="-2.6179939" upper="2.6179939" velocity="5.6548668"/>
  </joint>
  <joint name="jd_11" type="fixed">
    <parent link="fd_10"/>
    <child link="f_11"/>
    <origin rpy="-1.5707963267948966 -0.0 -1.5707963267948966" xyz="0.0 -0.0 -0.04"/>
  </joint>
  <link name="f_11"/>
  <link name="fd_11"/>
  <joint name="j_8" type="revolute">
    <parent link="f_11"/>
    <child link="fd_11"/>
    <axis xyz="0 0 1"/>
    <limit effort="10" lower="-2.6179939" upper="2.6179939" velocity="5.6548668"/>
  </joint>
  <joint name="jd_12" type="fixed">
    <parent link="fd_11"/>
    <child link="f_12"/>
    <origin rpy="1.5707963267948966 -0.0 1.5707963267948966" xyz="0.0 0.0 0.0"/>
  </joint>
  <link name="f_12"/>
  <link name="fd_12"/>
  <joint name="j_9" type="revolute">
    <parent link="f_12"/>
    <child link="fd_12"/>
    <axis xyz="0 0 1"/>
    <limit effort="10" lower="-2.6179939" upper="2.6179939" velocity="5.6548668"/>
  </joint>
  <joint name="jd_13" type="fixed">
    <parent link="fd_12"/>
    <child link="f_13"/>
    <origin rpy="-1.5707963267948966 -0.0 0.0" xyz="0.3 0.0 0.0"/>
  </joint>
  <link name="f_13"/>
  <link name="fd_13"/>
  <joint name="j_10" type="revolute">
    <parent link="f_13"/>
    <child link="fd_13"/>
    <axis xyz="0 0 1"/>
    <limit effort="10" lower="-2.6179939" upper="2.6179939" velocity="5.6548668"/>
  </joint>
  <joint name="jd_14" type="fixed">
    <parent link="fd_13"/>
    <child link="f_14"/>
    <origin rpy="0.0 -0.0 0.0" xyz="0.315 0.0 0.0"/>
  </joint>
  <link name="f_14"/>
  <link name="fd_14"/>
  <joint name="j_11" type="revolute">
    <parent link="f_14"/>
    <child link="fd_14"/>
    <axis xyz="0 0 1"/>
    <limit effort="10" lower="-2.6179939" upper="2.6179939" velocity="5.6548668"/>
  </joint>
  <joint name="jd_15" type="fixed">
    <parent link="fd_14"/>
    <child link="f_15"/>
    <origin rpy="1.5707963267948966 -0.0 0.0" xyz="0.0 0.0 0.0"/>
  </joint>
  <link name="f_15"/>
  <link name="fd_15"/>
  <joint name="j_12" type="revolute">
    <parent link="f_15"/>
    <child link="fd_15"/>
    <axis xyz="0 0 1"/>
    <limit effort="10" lower="-2.6179939" upper="2.6179939" velocity="5.6548668"/>
  </joint>
  <joint name="jd_16" type="fixed">
    <parent link="fd_15"/>
    <child link="f_16"/>
    <origin rpy="-1.5707963267948966 -0.0 0.0" xyz="0.045 0.0 0.0"/>
  </joint>
  <link name="f_16"/>
  <link name="fd_16"/>
  <joint name="jf_3" type="fixed">
    <parent link="f_16"/>
    <child link="fd_16"/>
  </joint>
  <joint name="jd_17" type="fixed">
    <parent link="fd_16"/>
    <child link="f_17"/>
    <origin rpy="1.5707963267948966 -0.0 -1.5707963267948966" xyz="3.55147571753e-18 -0.058 0.0"/>
  </joint>
  <link name="f_17"/>
  <link name="fd_17"/>
  <joint name="jf_4" type="fixed">
    <parent link="f_17"/>
    <child link="fd_17"/>
  </joint>
  <joint name="jd_20" type="fixed">
    <parent link="fd_base_link"/>
    <child link="f_20"/>
    <origin rpy="0.0 -0.0 0.0" xyz="0.0 0.0 0.29"/>
  </joint>
  <link name="f_20"/>
  <link name="fd_20"/>
  <joint name="jf_5" type="fixed">
    <parent link="f_20"/>
    <child link="fd_20"/>
  </joint>
  <joint name="jd_21" type="fixed">
    <parent link="fd_20"/>
    <child link="f_21"/>
    <origin rpy="-1.5707963267948966 -0.0 0.0" xyz="0.0 0.0 0.0"/>
  </joint>
  <link name="f_21"/>
  <link name="fd_21"/>
  <joint name="j_13" type="revolute">
    <parent link="f_21"/>
    <child link="fd_21"/>
    <axis xyz="0 0 1"/>
    <limit effort="10" lower="-2.6179939" upper="2.6179939" velocity="5.6548668"/>
  </joint>
  <joint name="jd_22" type="fixed">
    <parent link="fd_21"/>
    <child link="f_22"/>
    <origin rpy="1.5707963267948966 -0.0 1.5707963267948966" xyz="0.0 0.0 -0.145"/>
  </joint>
  <link name="f_22"/>
  <link name="fd_22"/>
  <joint name="jf_6" type="fixed">
    <parent link="f_22"/>
    <child link="fd_22"/>
  </joint>
  <joint name="jd_23" type="fixed">
    <parent link="fd_22"/>
    <child link="f_23"/>
    <origin rpy="0.0 -0.0 0.0" xyz="0.32 0.0 0.0"/>
  </joint>
  <link name="f_23"/>
  <link name="fd_23"/>
  <joint name="jf_7" type="fixed">
    <parent link="f_23"/>
    <child link="fd_23"/>
  </joint>
  <joint name="jd_30" type="fixed">
    <parent link="fd_base_link"/>
    <child link="f_30"/>
    <origin rpy="0.0 -0.0 0.0" xyz="0.0 0.0 0.29"/>
  </joint>
  <link name="f_30"/>
  <link name="fd_30"/>
  <joint name="jf_8" type="fixed">
    <parent link="f_30"/>
    <child link="fd_30"/>
  </joint>
  <joint name="jd_31" type="fixed">
    <parent link="fd_30"/>
    <child link="f_31"/>
    <origin rpy="-1.5707963267948966 -0.0 0.0" xyz="0.0 0.0 0.0"/>
  </joint>
  <link name="f_31"/>
  <link name="fd_31"/>
  <joint name="j_14" type="revolute">
    <parent link="f_31"/>
    <child link="fd_31"/>
    <axis xyz="0 0 1"/>
    <limit effort="10" lower="-2.6179939" upper="2.6179939" velocity="5.6548668"/>
  </joint>
  <joint name="jd_32" type="fixed">
    <parent link="fd_31"/>
    <child link="f_32"/>
    <origin rpy="-1.5707963267948966 -0.0 -1.5707963267948966" xyz="0.0 -0.0 -0.145"/>
  </joint>
  <link name="f_32"/>
  <link name="fd_32"/>
  <joint name="jf_9" type="fixed">
    <parent link="f_32"/>
    <child link="fd_32"/>
  </joint>
  <joint name="jd_33" type="fixed">
    <parent link="fd_32"/>
    <child link="f_33"/>
    <origin rpy="0.0 -0.0 0.0" xyz="0.32 0.0 0.0"/>
  </joint>
  <link name="f_33"/>
  <link name="fd_33"/>
  <joint name="jf_10" type="fixed">
    <parent link="f_33"/>
    <child link="fd_33"/>
  </joint>
</robot>

